[2021-12-17 09:50:39,422: INFO/MainProcess] Connected to redis://redis:6379/0
[2021-12-17 09:50:39,460: INFO/MainProcess] mingle: searching for neighbors
[2021-12-17 09:50:40,496: INFO/MainProcess] mingle: all alone
[2021-12-17 09:50:40,526: INFO/MainProcess] celery@worker ready.
[2021-12-17 09:51:14,542: INFO/MainProcess] Task celery_app.add[c96617b1-5cf7-423c-9e51-cd74b2e9c574] received
[2021-12-17 09:52:54,510: INFO/ForkPoolWorker-1] Task celery_app.add[c96617b1-5cf7-423c-9e51-cd74b2e9c574] succeeded in 100.04670926400013s: 7
[2021-12-17 09:53:14,306: INFO/MainProcess] Task celery_app.add[f3b7edd6-2ca0-4b32-a0a9-1086421c1ead] received
[2021-12-17 09:54:54,263: INFO/ForkPoolWorker-1] Task celery_app.add[f3b7edd6-2ca0-4b32-a0a9-1086421c1ead] succeeded in 100.03439320000007s: 105
[2021-12-17 10:02:37,874: INFO/MainProcess] Task celery_app.add[600f06a9-c4de-4d77-bf6a-d6aa2a696afb] received
[2021-12-17 10:04:17,885: INFO/ForkPoolWorker-1] Task celery_app.add[600f06a9-c4de-4d77-bf6a-d6aa2a696afb] succeeded in 100.08728766800004s: 239
[2021-12-17 11:01:15,427: INFO/MainProcess] Task celery_app.add[d5be0240-f061-451f-9747-9888fd89ebac] received
[2021-12-17 11:02:55,581: INFO/ForkPoolWorker-1] Task celery_app.add[d5be0240-f061-451f-9747-9888fd89ebac] succeeded in 100.18319533700014s: 65
[2021-12-17 11:24:36,448: INFO/MainProcess] Connected to redis://redis:6379/0
[2021-12-17 11:24:36,468: INFO/MainProcess] mingle: searching for neighbors
[2021-12-17 11:24:37,494: INFO/MainProcess] mingle: all alone
[2021-12-17 11:24:37,523: INFO/MainProcess] celery@worker ready.
[2021-12-17 14:01:38,417: INFO/MainProcess] Task celery_app.add[1a58468f-1529-4d42-a077-1593264b8fe4] received
[2021-12-17 14:01:58,523: ERROR/ForkPoolWorker-1] Task celery_app.add[1a58468f-1529-4d42-a077-1593264b8fe4] raised unexpected: TypeError("unsupported operand type(s) for +: 'NoneType' and 'NoneType'")
Traceback (most recent call last):
  File "/usr/local/lib/python3.10/site-packages/celery/app/trace.py", line 451, in trace_task
    R = retval = fun(*args, **kwargs)
  File "/usr/local/lib/python3.10/site-packages/celery/app/trace.py", line 734, in __protected_call__
    return self.run(*args, **kwargs)
  File "/app/celery_app.py", line 13, in add
    return x + y
TypeError: unsupported operand type(s) for +: 'NoneType' and 'NoneType'
[2021-12-17 15:06:01,807: ERROR/MainProcess] Received unregistered task of type 'celery_app.add_task'.
The message has been ignored and discarded.

Did you remember to import the module containing this task?
Or maybe you're using relative imports?

Please see
http://docs.celeryq.org/en/latest/internals/protocol.html
for more information.

The full contents of the message body was:
b'[[3, 5], {}, {"callbacks": null, "errbacks": null, "chain": null, "chord": null}]' (81b)
Traceback (most recent call last):
  File "/usr/local/lib/python3.10/site-packages/celery/worker/consumer/consumer.py", line 581, in on_task_received
    strategy = strategies[type_]
KeyError: 'celery_app.add_task'
[2021-12-17 15:07:58,315: ERROR/MainProcess] Received unregistered task of type 'celery_app.add_task'.
The message has been ignored and discarded.

Did you remember to import the module containing this task?
Or maybe you're using relative imports?

Please see
http://docs.celeryq.org/en/latest/internals/protocol.html
for more information.

The full contents of the message body was:
b'[[3, 5], {}, {"callbacks": null, "errbacks": null, "chain": null, "chord": null}]' (81b)
Traceback (most recent call last):
  File "/usr/local/lib/python3.10/site-packages/celery/worker/consumer/consumer.py", line 581, in on_task_received
    strategy = strategies[type_]
KeyError: 'celery_app.add_task'
[2021-12-17 15:09:21,557: ERROR/MainProcess] Received unregistered task of type 'celery_app.add_task'.
The message has been ignored and discarded.

Did you remember to import the module containing this task?
Or maybe you're using relative imports?

Please see
http://docs.celeryq.org/en/latest/internals/protocol.html
for more information.

The full contents of the message body was:
b'[[3, 6], {}, {"callbacks": null, "errbacks": null, "chain": null, "chord": null}]' (81b)
Traceback (most recent call last):
  File "/usr/local/lib/python3.10/site-packages/celery/worker/consumer/consumer.py", line 581, in on_task_received
    strategy = strategies[type_]
KeyError: 'celery_app.add_task'
[2021-12-17 15:09:37,219: ERROR/MainProcess] Received unregistered task of type 'celery_app.add_task'.
The message has been ignored and discarded.

Did you remember to import the module containing this task?
Or maybe you're using relative imports?

Please see
http://docs.celeryq.org/en/latest/internals/protocol.html
for more information.

The full contents of the message body was:
b'[[3, 7], {}, {"callbacks": null, "errbacks": null, "chain": null, "chord": null}]' (81b)
Traceback (most recent call last):
  File "/usr/local/lib/python3.10/site-packages/celery/worker/consumer/consumer.py", line 581, in on_task_received
    strategy = strategies[type_]
KeyError: 'celery_app.add_task'
[2021-12-17 15:11:41,105: ERROR/MainProcess] Received unregistered task of type 'celery_app.add_task'.
The message has been ignored and discarded.

Did you remember to import the module containing this task?
Or maybe you're using relative imports?

Please see
http://docs.celeryq.org/en/latest/internals/protocol.html
for more information.

The full contents of the message body was:
b'[[3, 7], {}, {"callbacks": null, "errbacks": null, "chain": null, "chord": null}]' (81b)
Traceback (most recent call last):
  File "/usr/local/lib/python3.10/site-packages/celery/worker/consumer/consumer.py", line 581, in on_task_received
    strategy = strategies[type_]
KeyError: 'celery_app.add_task'
[2021-12-17 15:13:26,786: INFO/MainProcess] Connected to redis://redis:6379/0
[2021-12-17 15:13:26,804: INFO/MainProcess] mingle: searching for neighbors
[2021-12-17 15:13:27,833: INFO/MainProcess] mingle: all alone
[2021-12-17 15:13:27,864: INFO/MainProcess] celery@worker ready.
[2021-12-17 15:14:46,480: INFO/MainProcess] Task celery_app.add_task[e9f5ef11-a479-4888-a64b-daf8534de535] received
[2021-12-17 15:14:46,494: INFO/MainProcess] Task celery_app.add_task[8dc58463-564c-4cf8-bbd7-f6c858bba181] received
[2021-12-17 15:15:06,480: INFO/ForkPoolWorker-1] Task celery_app.add_task[e9f5ef11-a479-4888-a64b-daf8534de535] succeeded in 20.027662699998473s: 10
[2021-12-17 15:15:06,507: INFO/ForkPoolWorker-2] Task celery_app.add_task[8dc58463-564c-4cf8-bbd7-f6c858bba181] succeeded in 20.033075800001825s: 10
[2021-12-17 15:55:24,826: INFO/MainProcess] Task celery_app.add_task[9b918b1a-80ec-4ebe-8bcf-b8c1142fce86] received
[2021-12-17 15:55:24,851: INFO/MainProcess] Task celery_app.add_task[9f0b3767-e58b-4d9d-84eb-fd4067873181] received
[2021-12-17 15:55:44,845: INFO/ForkPoolWorker-1] Task celery_app.add_task[9b918b1a-80ec-4ebe-8bcf-b8c1142fce86] succeeded in 20.006840300000476s: 3
[2021-12-17 15:55:44,883: INFO/ForkPoolWorker-2] Task celery_app.add_task[9f0b3767-e58b-4d9d-84eb-fd4067873181] succeeded in 20.022758499999327s: 3
[2021-12-17 15:56:40,097: INFO/MainProcess] Task celery_app.add_task[e690423f-c0b0-4739-8870-fe228320a124] received
[2021-12-17 15:56:40,110: INFO/MainProcess] Task celery_app.add_task[acd52c55-9a9d-4519-8345-6d05defd984b] received
[2021-12-17 15:57:00,091: INFO/ForkPoolWorker-1] Task celery_app.add_task[e690423f-c0b0-4739-8870-fe228320a124] succeeded in 20.022993900001893s: 6
[2021-12-17 15:57:00,095: INFO/ForkPoolWorker-2] Task celery_app.add_task[acd52c55-9a9d-4519-8345-6d05defd984b] succeeded in 20.009210100000928s: 5
[2021-12-17 15:59:34,712: INFO/MainProcess] Connected to redis://redis:6379/0
[2021-12-17 15:59:34,725: INFO/MainProcess] mingle: searching for neighbors
[2021-12-17 15:59:35,764: INFO/MainProcess] mingle: all alone
[2021-12-17 15:59:35,794: INFO/MainProcess] celery@worker ready.
[2021-12-17 16:00:29,635: INFO/MainProcess] Task celery_app.add_task[a1300972-a965-4359-b9a1-0080ec0153ac] received
[2021-12-17 16:00:29,649: INFO/MainProcess] Task celery_app.add_task[a2c3a8e6-6451-4f25-abee-d748f7af4fd3] received
[2021-12-17 16:02:09,810: INFO/ForkPoolWorker-1] Task celery_app.add_task[a1300972-a965-4359-b9a1-0080ec0153ac] succeeded in 100.0148868000033s: 10
[2021-12-17 16:02:09,832: INFO/ForkPoolWorker-2] Task celery_app.add_task[a2c3a8e6-6451-4f25-abee-d748f7af4fd3] succeeded in 100.02174519999971s: 10
[2021-12-17 16:16:26,296: INFO/MainProcess] Task celery_app.add_task[028e381b-cb28-4a51-a914-f8ac5db0a8da] received
[2021-12-17 16:18:06,262: INFO/ForkPoolWorker-1] Task celery_app.add_task[028e381b-cb28-4a51-a914-f8ac5db0a8da] succeeded in 100.06169070000033s: 10
[2021-12-17 16:18:42,882: INFO/MainProcess] Task celery_app.add_task[b0144b1b-e24b-43b5-89ec-08cc9d47a192] received
[2021-12-17 16:20:22,835: INFO/ForkPoolWorker-1] Task celery_app.add_task[b0144b1b-e24b-43b5-89ec-08cc9d47a192] succeeded in 100.08125350000046s: 10
[2021-12-17 16:27:37,063: INFO/MainProcess] Task celery_app.add_task[58aaffad-988d-4b9f-88b6-1d7dc4f8ec14] received
[2021-12-17 16:29:17,032: ERROR/ForkPoolWorker-1] Task celery_app.add_task[58aaffad-988d-4b9f-88b6-1d7dc4f8ec14] raised unexpected: TypeError("unsupported operand type(s) for +: 'NoneType' and 'NoneType'")
Traceback (most recent call last):
  File "/usr/local/lib/python3.10/site-packages/celery/app/trace.py", line 451, in trace_task
    R = retval = fun(*args, **kwargs)
  File "/usr/local/lib/python3.10/site-packages/celery/app/trace.py", line 734, in __protected_call__
    return self.run(*args, **kwargs)
  File "/app/celery_app.py", line 13, in add_task
    return x + y
TypeError: unsupported operand type(s) for +: 'NoneType' and 'NoneType'
[2021-12-17 16:31:40,274: INFO/MainProcess] Task celery_app.add_task[0e2dda35-1293-4d54-9026-3a72087c42b7] received
[2021-12-17 16:33:20,190: INFO/ForkPoolWorker-1] Task celery_app.add_task[0e2dda35-1293-4d54-9026-3a72087c42b7] succeeded in 100.04280069999731s: 8
[2021-12-17 16:34:28,287: INFO/MainProcess] Task celery_app.add_task[ed7b089a-2e78-44cc-8619-7b74a6665291] received
[2021-12-17 16:36:08,254: ERROR/ForkPoolWorker-1] Task celery_app.add_task[ed7b089a-2e78-44cc-8619-7b74a6665291] raised unexpected: TypeError("unsupported operand type(s) for +: 'NoneType' and 'NoneType'")
Traceback (most recent call last):
  File "/usr/local/lib/python3.10/site-packages/celery/app/trace.py", line 451, in trace_task
    R = retval = fun(*args, **kwargs)
  File "/usr/local/lib/python3.10/site-packages/celery/app/trace.py", line 734, in __protected_call__
    return self.run(*args, **kwargs)
  File "/app/celery_app.py", line 13, in add_task
    return int(x) + int(y)
TypeError: unsupported operand type(s) for +: 'NoneType' and 'NoneType'
[2021-12-17 16:42:01,295: INFO/MainProcess] Task celery_app.add_task[aa0dab03-bdc6-40d8-b9b1-acbc1e313545] received
[2021-12-17 16:43:41,228: ERROR/ForkPoolWorker-1] Task celery_app.add_task[aa0dab03-bdc6-40d8-b9b1-acbc1e313545] raised unexpected: TypeError("unsupported operand type(s) for +: 'NoneType' and 'NoneType'")
Traceback (most recent call last):
  File "/usr/local/lib/python3.10/site-packages/celery/app/trace.py", line 451, in trace_task
    R = retval = fun(*args, **kwargs)
  File "/usr/local/lib/python3.10/site-packages/celery/app/trace.py", line 734, in __protected_call__
    return self.run(*args, **kwargs)
  File "/app/celery_app.py", line 13, in add_task
    return x + y
TypeError: unsupported operand type(s) for +: 'NoneType' and 'NoneType'
[2021-12-17 16:47:27,465: INFO/MainProcess] Task celery_app.add_task[ed53719c-1e59-4b48-956c-e46c461aa5d1] received
[2021-12-17 16:49:07,465: ERROR/ForkPoolWorker-1] Task celery_app.add_task[ed53719c-1e59-4b48-956c-e46c461aa5d1] raised unexpected: TypeError("unsupported operand type(s) for +: 'NoneType' and 'NoneType'")
Traceback (most recent call last):
  File "/usr/local/lib/python3.10/site-packages/celery/app/trace.py", line 451, in trace_task
    R = retval = fun(*args, **kwargs)
  File "/usr/local/lib/python3.10/site-packages/celery/app/trace.py", line 734, in __protected_call__
    return self.run(*args, **kwargs)
  File "/app/celery_app.py", line 13, in add_task
    return x + y
TypeError: unsupported operand type(s) for +: 'NoneType' and 'NoneType'
[2021-12-17 16:51:30,001: INFO/MainProcess] Task celery_app.add_task[d11f249c-08b3-4b86-b262-f62d02929275] received
[2021-12-17 16:53:10,013: ERROR/ForkPoolWorker-1] Task celery_app.add_task[d11f249c-08b3-4b86-b262-f62d02929275] raised unexpected: TypeError("unsupported operand type(s) for +: 'NoneType' and 'NoneType'")
Traceback (most recent call last):
  File "/usr/local/lib/python3.10/site-packages/celery/app/trace.py", line 451, in trace_task
    R = retval = fun(*args, **kwargs)
  File "/usr/local/lib/python3.10/site-packages/celery/app/trace.py", line 734, in __protected_call__
    return self.run(*args, **kwargs)
  File "/app/celery_app.py", line 13, in add_task
    return x + y
TypeError: unsupported operand type(s) for +: 'NoneType' and 'NoneType'
[2021-12-17 16:54:25,730: INFO/MainProcess] Task celery_app.add_task[b74f4db2-5b7d-4dab-a8b6-667b15b25a7f] received
[2021-12-17 16:56:05,738: INFO/ForkPoolWorker-1] Task celery_app.add_task[b74f4db2-5b7d-4dab-a8b6-667b15b25a7f] succeeded in 100.0969045999991s: 8
[2021-12-17 17:09:40,345: INFO/MainProcess] Task celery_app.add_task[a7fbb3b6-3446-4ab0-bec7-d204b0e7222e] received
[2021-12-17 17:11:20,330: ERROR/ForkPoolWorker-1] Task celery_app.add_task[a7fbb3b6-3446-4ab0-bec7-d204b0e7222e] raised unexpected: TypeError("unsupported operand type(s) for +: 'NoneType' and 'NoneType'")
Traceback (most recent call last):
  File "/usr/local/lib/python3.10/site-packages/celery/app/trace.py", line 451, in trace_task
    R = retval = fun(*args, **kwargs)
  File "/usr/local/lib/python3.10/site-packages/celery/app/trace.py", line 734, in __protected_call__
    return self.run(*args, **kwargs)
  File "/app/celery_app.py", line 13, in add_task
    return x + y
TypeError: unsupported operand type(s) for +: 'NoneType' and 'NoneType'
[2021-12-17 17:23:21,900: INFO/MainProcess] Task celery_app.add_task[f8665e3f-af03-46a1-8fbd-7ff570ac031b] received
[2021-12-17 17:25:01,813: INFO/ForkPoolWorker-1] Task celery_app.add_task[f8665e3f-af03-46a1-8fbd-7ff570ac031b] succeeded in 100.01175049999802s: 7
[2021-12-17 17:26:54,448: INFO/MainProcess] Task celery_app.add_task[7c8465d3-9a38-43e1-829e-ab21cf6f224c] received
[2021-12-17 17:26:54,465: INFO/MainProcess] Task celery_app.add_task[6a0fdb54-910d-448b-84fd-3921c062efbc] received
[2021-12-17 17:28:34,415: INFO/ForkPoolWorker-1] Task celery_app.add_task[7c8465d3-9a38-43e1-829e-ab21cf6f224c] succeeded in 100.06207319999885s: 10
[2021-12-17 17:28:34,430: INFO/ForkPoolWorker-2] Task celery_app.add_task[6a0fdb54-910d-448b-84fd-3921c062efbc] succeeded in 100.05132009999943s: 10
[2021-12-17 17:29:31,136: INFO/MainProcess] Task celery_app.add_task[dbcea43f-dd0c-4ac9-99cb-de4a897d75a7] received
[2021-12-17 17:31:11,144: INFO/ForkPoolWorker-1] Task celery_app.add_task[dbcea43f-dd0c-4ac9-99cb-de4a897d75a7] succeeded in 100.10138749999896s: 17
[2021-12-17 17:40:59,691: INFO/MainProcess] Task celery_app.add_task[ac0e1290-0f7b-493a-b7e5-b757898c8214] received
[2021-12-17 17:42:39,652: INFO/ForkPoolWorker-1] Task celery_app.add_task[ac0e1290-0f7b-493a-b7e5-b757898c8214] succeeded in 100.05344590000095s: 7
[2021-12-21 14:06:00,528: INFO/MainProcess] Connected to redis://redis:6379/0
[2021-12-21 14:06:00,555: INFO/MainProcess] mingle: searching for neighbors
[2021-12-21 14:06:01,635: INFO/MainProcess] mingle: all alone
[2021-12-21 14:06:01,657: INFO/MainProcess] celery@worker ready.
[2021-12-21 14:17:56,561: INFO/MainProcess] Task celery_app.add_task[322b636a-808d-4d7d-87d3-8caef6973d11] received
[2021-12-21 14:18:11,638: INFO/ForkPoolWorker-1] Task celery_app.add_task[322b636a-808d-4d7d-87d3-8caef6973d11] succeeded in 15.081349063999824s: 10
[2022-01-06 10:06:33,278: INFO/MainProcess] Connected to redis://redis:6379/0
[2022-01-06 10:06:33,287: INFO/MainProcess] mingle: searching for neighbors
[2022-01-06 10:06:34,311: INFO/MainProcess] mingle: all alone
[2022-01-06 10:06:34,330: INFO/MainProcess] celery@worker ready.
[2022-01-06 10:07:07,438: INFO/MainProcess] Task celery_app.add_task[84e0b291-7764-43b1-b917-1bee007704e7] received
[2022-01-06 10:07:22,452: INFO/ForkPoolWorker-1] Task celery_app.add_task[84e0b291-7764-43b1-b917-1bee007704e7] succeeded in 15.030010291000053s: 10
[2022-01-06 10:09:17,395: INFO/MainProcess] Connected to redis://redis:6379/0
[2022-01-06 10:09:17,409: INFO/MainProcess] mingle: searching for neighbors
[2022-01-06 10:09:18,415: INFO/MainProcess] mingle: all alone
[2022-01-06 10:09:18,436: INFO/MainProcess] celery@worker ready.
[2022-01-06 10:12:57,296: INFO/MainProcess] Connected to redis://redis:6379/0
[2022-01-06 10:12:57,303: INFO/MainProcess] mingle: searching for neighbors
[2022-01-06 10:12:58,324: INFO/MainProcess] mingle: all alone
[2022-01-06 10:12:58,344: INFO/MainProcess] celery@worker ready.
[2022-01-06 10:13:39,537: INFO/MainProcess] Task celery_app.add_task[ef1cc849-9e10-4eb6-8620-60eef01c7d9f] received
[2022-01-06 10:13:54,548: WARNING/ForkPoolWorker-1] pdb is running on 127.0.0.1:4444
[2022-01-06 10:24:52,583: INFO/MainProcess] Connected to redis://redis:6379/0
[2022-01-06 10:24:52,590: INFO/MainProcess] mingle: searching for neighbors
[2022-01-06 10:24:53,610: INFO/MainProcess] mingle: all alone
[2022-01-06 10:24:53,631: INFO/MainProcess] celery@worker ready.
[2022-01-06 10:25:31,853: INFO/MainProcess] Task celery_app.add_task[c14deab6-9ade-476f-aaff-fff6ab8615e3] received
[2022-01-06 10:25:46,872: WARNING/ForkPoolWorker-1] pdb is running on 0.0.0.0:4444
[2022-01-06 10:33:41,565: INFO/MainProcess] Connected to redis://redis:6379/0
[2022-01-06 10:33:41,576: INFO/MainProcess] mingle: searching for neighbors
[2022-01-06 10:33:42,596: INFO/MainProcess] mingle: all alone
[2022-01-06 10:33:42,613: INFO/MainProcess] celery@worker ready.
[2022-01-06 10:33:46,311: INFO/MainProcess] Task celery_app.add_task[021e345b-84ce-422f-bc14-f56e500869c1] received
[2022-01-06 10:34:01,329: WARNING/ForkPoolWorker-1] pdb is running on 0.0.0.0:4444
[2022-01-06 10:41:22,599: INFO/MainProcess] Connected to redis://redis:6379/0
[2022-01-06 10:41:22,606: INFO/MainProcess] mingle: searching for neighbors
[2022-01-06 10:41:23,623: INFO/MainProcess] mingle: all alone
[2022-01-06 10:41:23,640: INFO/MainProcess] celery@worker ready.
[2022-01-06 10:41:30,208: INFO/MainProcess] Task celery_app.add_task[154867cc-f7d1-40f4-aeef-52f02096d31a] received
[2022-01-06 10:41:45,268: WARNING/ForkPoolWorker-1] pdb is running on 0.0.0.0:4444
[2022-01-06 11:30:57,796: INFO/MainProcess] Connected to redis://redis:6379/0
[2022-01-06 11:30:57,805: INFO/MainProcess] mingle: searching for neighbors
[2022-01-06 11:30:58,822: INFO/MainProcess] mingle: all alone
[2022-01-06 11:30:58,840: INFO/MainProcess] celery@worker ready.
[2022-01-06 11:31:39,432: INFO/MainProcess] Task celery_app.add_task[61d79bc0-79e7-40dc-bf76-dd9883258399] received
[2022-01-06 11:36:51,498: INFO/MainProcess] Connected to redis://redis:6379/0
[2022-01-06 11:36:51,508: INFO/MainProcess] mingle: searching for neighbors
[2022-01-06 11:36:52,527: INFO/MainProcess] mingle: all alone
[2022-01-06 11:36:52,550: INFO/MainProcess] celery@worker ready.
[2022-01-06 11:38:59,407: INFO/MainProcess] Connected to redis://redis:6379/0
[2022-01-06 11:38:59,414: INFO/MainProcess] mingle: searching for neighbors
[2022-01-06 11:39:00,432: INFO/MainProcess] mingle: all alone
[2022-01-06 11:39:00,451: INFO/MainProcess] celery@worker ready.
[2022-01-06 11:39:32,616: INFO/MainProcess] Task celery_app.add_task[6b6e8334-8fd2-4755-9643-a321b9e0d0fa] received
[2022-01-06 11:39:47,651: WARNING/ForkPoolWorker-1] pdb is running on 0.0.0.0:4444
[2022-01-06 15:07:58,570: INFO/MainProcess] Connected to redis://redis:6379/0
[2022-01-06 15:07:58,598: INFO/MainProcess] mingle: searching for neighbors
[2022-01-06 15:07:59,643: INFO/MainProcess] mingle: all alone
[2022-01-06 15:07:59,676: INFO/MainProcess] celery@worker ready.
[2022-01-06 15:08:26,118: INFO/MainProcess] Task celery_app.add_task[c3a5b3d2-f86c-46b2-b2f5-5bbaa6defec9] received
[2022-01-06 15:08:26,142: INFO/MainProcess] Task celery_app.add_task[18decb3e-40d9-4cdd-a871-cfa98c8f2a4c] received
[2022-01-06 15:08:41,302: WARNING/ForkPoolWorker-1] pdb is running on 0.0.0.0:4444
[2022-01-06 15:08:41,367: ERROR/ForkPoolWorker-2] Task celery_app.add_task[18decb3e-40d9-4cdd-a871-cfa98c8f2a4c] raised unexpected: OSError(98, 'Address already in use')
Traceback (most recent call last):
  File "/usr/local/lib/python3.10/site-packages/celery/app/trace.py", line 451, in trace_task
    R = retval = fun(*args, **kwargs)
  File "/usr/local/lib/python3.10/site-packages/celery/app/trace.py", line 734, in __protected_call__
    return self.run(*args, **kwargs)
  File "/app/celery_app.py", line 15, in add_task
    import rpdb; rpdb.Rpdb(addr='0.0.0.0', port=4444).set_trace()
  File "/usr/local/lib/python3.10/site-packages/rpdb/__init__.py", line 46, in __init__
    self.skt.bind((addr, port))
OSError: [Errno 98] Address already in use
[2022-01-06 15:10:32,300: INFO/MainProcess] Task celery_app.add_task[deff384f-d2c0-4221-b055-9dd5fa5232f7] received
[2022-01-06 15:10:47,385: ERROR/ForkPoolWorker-2] Task celery_app.add_task[deff384f-d2c0-4221-b055-9dd5fa5232f7] raised unexpected: OSError(98, 'Address already in use')
Traceback (most recent call last):
  File "/usr/local/lib/python3.10/site-packages/celery/app/trace.py", line 451, in trace_task
    R = retval = fun(*args, **kwargs)
  File "/usr/local/lib/python3.10/site-packages/celery/app/trace.py", line 734, in __protected_call__
    return self.run(*args, **kwargs)
  File "/app/celery_app.py", line 15, in add_task
    import rpdb; rpdb.Rpdb(addr='0.0.0.0', port=4444).set_trace()
  File "/usr/local/lib/python3.10/site-packages/rpdb/__init__.py", line 46, in __init__
    self.skt.bind((addr, port))
OSError: [Errno 98] Address already in use
[2022-01-06 15:16:17,232: INFO/MainProcess] Connected to redis://redis:6379/0
[2022-01-06 15:16:17,252: INFO/MainProcess] mingle: searching for neighbors
[2022-01-06 15:16:18,266: INFO/MainProcess] mingle: all alone
[2022-01-06 15:16:18,304: INFO/MainProcess] celery@worker ready.
[2022-01-06 15:17:25,360: INFO/MainProcess] Task celery_app.add_task[bc4ecaf0-adaa-45d7-b274-6d751fc590e3] received
[2022-01-06 15:17:40,462: WARNING/ForkPoolWorker-1] pdb is running on 0.0.0.0:4444
[2022-01-06 15:17:54,374: ERROR/ForkPoolWorker-1] Task celery_app.add_task[bc4ecaf0-adaa-45d7-b274-6d751fc590e3] raised unexpected: BdbQuit()
Traceback (most recent call last):
  File "/usr/local/lib/python3.10/site-packages/celery/app/trace.py", line 451, in trace_task
    R = retval = fun(*args, **kwargs)
  File "/usr/local/lib/python3.10/site-packages/celery/app/trace.py", line 734, in __protected_call__
    return self.run(*args, **kwargs)
  File "/app/celery_app.py", line 17, in add_task
    return result
  File "/app/celery_app.py", line 17, in add_task
    return result
  File "/usr/local/lib/python3.10/bdb.py", line 90, in trace_dispatch
    return self.dispatch_line(frame)
  File "/usr/local/lib/python3.10/bdb.py", line 115, in dispatch_line
    if self.quitting: raise BdbQuit
bdb.BdbQuit
[2022-01-06 15:18:12,178: INFO/MainProcess] Task celery_app.add_task[c0b49598-375f-4fb2-b126-cb817657698b] received
[2022-01-06 15:18:27,172: WARNING/ForkPoolWorker-1] pdb is running on 0.0.0.0:4444
[2022-01-06 15:19:18,597: ERROR/ForkPoolWorker-1] Task celery_app.add_task[c0b49598-375f-4fb2-b126-cb817657698b] raised unexpected: BdbQuit()
Traceback (most recent call last):
  File "/usr/local/lib/python3.10/site-packages/celery/app/trace.py", line 451, in trace_task
    R = retval = fun(*args, **kwargs)
  File "/usr/local/lib/python3.10/site-packages/celery/app/trace.py", line 734, in __protected_call__
    return self.run(*args, **kwargs)
  File "/app/celery_app.py", line 17, in add_task
    return result
  File "/app/celery_app.py", line 17, in add_task
    return result
  File "/usr/local/lib/python3.10/bdb.py", line 90, in trace_dispatch
    return self.dispatch_line(frame)
  File "/usr/local/lib/python3.10/bdb.py", line 115, in dispatch_line
    if self.quitting: raise BdbQuit
bdb.BdbQuit
[2022-01-06 15:20:07,984: INFO/MainProcess] Task celery_app.add_task[c65aefde-3b93-43f7-9c9f-5fbd19660aa8] received
[2022-01-06 15:20:08,033: INFO/MainProcess] Task celery_app.add_task[198f8283-ce6d-44a9-af78-f9d3862a23fc] received
[2022-01-06 15:20:22,973: WARNING/ForkPoolWorker-1] pdb is running on 0.0.0.0:4444
[2022-01-06 15:20:23,087: ERROR/ForkPoolWorker-2] Task celery_app.add_task[198f8283-ce6d-44a9-af78-f9d3862a23fc] raised unexpected: OSError(98, 'Address already in use')
Traceback (most recent call last):
  File "/usr/local/lib/python3.10/site-packages/celery/app/trace.py", line 451, in trace_task
    R = retval = fun(*args, **kwargs)
  File "/usr/local/lib/python3.10/site-packages/celery/app/trace.py", line 734, in __protected_call__
    return self.run(*args, **kwargs)
  File "/app/celery_app.py", line 15, in add_task
    import rpdb; rpdb.Rpdb(addr='0.0.0.0', port=4444).set_trace()
  File "/usr/local/lib/python3.10/site-packages/rpdb/__init__.py", line 46, in __init__
    self.skt.bind((addr, port))
OSError: [Errno 98] Address already in use
[2022-01-06 15:22:48,874: INFO/MainProcess] Connected to redis://redis:6379/0
[2022-01-06 15:22:48,899: INFO/MainProcess] mingle: searching for neighbors
[2022-01-06 15:22:49,936: INFO/MainProcess] mingle: all alone
[2022-01-06 15:22:50,025: INFO/MainProcess] celery@worker ready.
[2022-01-06 15:24:43,234: INFO/MainProcess] Task celery_app.add_task[6aafb73a-4718-45c5-b43f-562a78e21a17] received
[2022-01-06 15:24:58,470: WARNING/ForkPoolWorker-1] pdb is running on 0.0.0.0:4444
[2022-01-06 15:29:33,610: INFO/MainProcess] Connected to redis://redis:6379/0
[2022-01-06 15:29:33,629: INFO/MainProcess] mingle: searching for neighbors
[2022-01-06 15:29:34,670: INFO/MainProcess] mingle: all alone
[2022-01-06 15:29:34,701: INFO/MainProcess] celery@worker ready.
[2022-01-06 15:30:14,827: INFO/MainProcess] Task celery_app.add_task[6aa8b65f-6be1-4b19-804b-9c1e4c21b1f7] received
[2022-01-06 15:30:29,854: WARNING/ForkPoolWorker-1] pdb is running on 0.0.0.0:4444
[2022-01-06 15:31:07,721: ERROR/ForkPoolWorker-1] Task celery_app.add_task[6aa8b65f-6be1-4b19-804b-9c1e4c21b1f7] raised unexpected: UnicodeDecodeError('utf-8', b'\xff\xf4\xff\xfd\x06', 0, 1, 'invalid start byte')
Traceback (most recent call last):
  File "/usr/local/lib/python3.10/site-packages/celery/app/trace.py", line 451, in trace_task
    R = retval = fun(*args, **kwargs)
  File "/usr/local/lib/python3.10/site-packages/celery/app/trace.py", line 734, in __protected_call__
    return self.run(*args, **kwargs)
  File "/app/celery_app.py", line 17, in add_task
    return result
  File "/app/celery_app.py", line 17, in add_task
    return result
  File "/usr/local/lib/python3.10/bdb.py", line 90, in trace_dispatch
    return self.dispatch_line(frame)
  File "/usr/local/lib/python3.10/bdb.py", line 114, in dispatch_line
    self.user_line(frame)
  File "/usr/local/lib/python3.10/pdb.py", line 262, in user_line
    self.interaction(frame, None)
  File "/usr/local/lib/python3.10/pdb.py", line 357, in interaction
    self._cmdloop()
  File "/usr/local/lib/python3.10/pdb.py", line 322, in _cmdloop
    self.cmdloop()
  File "/usr/local/lib/python3.10/cmd.py", line 132, in cmdloop
    line = self.stdin.readline()
  File "/usr/local/lib/python3.10/codecs.py", line 322, in decode
    (result, consumed) = self._buffer_decode(data, self.errors, final)
UnicodeDecodeError: 'utf-8' codec can't decode byte 0xff in position 0: invalid start byte
[2022-01-06 16:21:27,003: INFO/MainProcess] Task celery_app.add_task[20238e6b-ebe0-449c-a195-71a3f95e89a9] received
[2022-01-06 16:21:42,047: ERROR/ForkPoolWorker-1] Task celery_app.add_task[20238e6b-ebe0-449c-a195-71a3f95e89a9] raised unexpected: OSError(98, 'Address already in use')
Traceback (most recent call last):
  File "/usr/local/lib/python3.10/site-packages/celery/app/trace.py", line 451, in trace_task
    R = retval = fun(*args, **kwargs)
  File "/usr/local/lib/python3.10/site-packages/celery/app/trace.py", line 734, in __protected_call__
    return self.run(*args, **kwargs)
  File "/app/celery_app.py", line 15, in add_task
    import rpdb; rpdb.Rpdb(addr='0.0.0.0', port=4444).set_trace()
  File "/usr/local/lib/python3.10/site-packages/rpdb/__init__.py", line 46, in __init__
    self.skt.bind((addr, port))
OSError: [Errno 98] Address already in use
[2022-01-06 16:22:57,419: INFO/MainProcess] Connected to redis://redis:6379/0
[2022-01-06 16:22:57,431: INFO/MainProcess] mingle: searching for neighbors
[2022-01-06 16:22:58,454: INFO/MainProcess] mingle: all alone
[2022-01-06 16:22:58,475: INFO/MainProcess] celery@worker ready.
[2022-01-06 16:23:43,433: INFO/MainProcess] Task celery_app.add_task[64a89386-f06f-44e0-bd9e-87299c06e090] received
[2022-01-06 16:23:58,455: WARNING/ForkPoolWorker-1] pdb is running on 0.0.0.0:4444
[2022-01-06 17:08:38,842: ERROR/ForkPoolWorker-1] Task celery_app.add_task[64a89386-f06f-44e0-bd9e-87299c06e090] raised unexpected: UnicodeDecodeError('utf-8', b'\xff\xf4\xff\xfd\x06', 0, 1, 'invalid start byte')
Traceback (most recent call last):
  File "/usr/local/lib/python3.10/site-packages/celery/app/trace.py", line 451, in trace_task
    R = retval = fun(*args, **kwargs)
  File "/usr/local/lib/python3.10/site-packages/celery/app/trace.py", line 734, in __protected_call__
    return self.run(*args, **kwargs)
  File "/app/celery_app.py", line 17, in add_task
    return result
  File "/usr/local/lib/python3.10/bdb.py", line 94, in trace_dispatch
    return self.dispatch_return(frame, arg)
  File "/usr/local/lib/python3.10/bdb.py", line 153, in dispatch_return
    self.user_return(frame, arg)
  File "/usr/local/lib/python3.10/pdb.py", line 294, in user_return
    self.interaction(frame, None)
  File "/usr/local/lib/python3.10/pdb.py", line 357, in interaction
    self._cmdloop()
  File "/usr/local/lib/python3.10/pdb.py", line 322, in _cmdloop
    self.cmdloop()
  File "/usr/local/lib/python3.10/cmd.py", line 132, in cmdloop
    line = self.stdin.readline()
  File "/usr/local/lib/python3.10/codecs.py", line 322, in decode
    (result, consumed) = self._buffer_decode(data, self.errors, final)
UnicodeDecodeError: 'utf-8' codec can't decode byte 0xff in position 0: invalid start byte
