[2021-12-17 09:50:39,422: INFO/MainProcess] Connected to redis://redis:6379/0
[2021-12-17 09:50:39,460: INFO/MainProcess] mingle: searching for neighbors
[2021-12-17 09:50:40,496: INFO/MainProcess] mingle: all alone
[2021-12-17 09:50:40,526: INFO/MainProcess] celery@worker ready.
[2021-12-17 09:51:14,542: INFO/MainProcess] Task celery_app.add[c96617b1-5cf7-423c-9e51-cd74b2e9c574] received
[2021-12-17 09:52:54,510: INFO/ForkPoolWorker-1] Task celery_app.add[c96617b1-5cf7-423c-9e51-cd74b2e9c574] succeeded in 100.04670926400013s: 7
[2021-12-17 09:53:14,306: INFO/MainProcess] Task celery_app.add[f3b7edd6-2ca0-4b32-a0a9-1086421c1ead] received
[2021-12-17 09:54:54,263: INFO/ForkPoolWorker-1] Task celery_app.add[f3b7edd6-2ca0-4b32-a0a9-1086421c1ead] succeeded in 100.03439320000007s: 105
[2021-12-17 10:02:37,874: INFO/MainProcess] Task celery_app.add[600f06a9-c4de-4d77-bf6a-d6aa2a696afb] received
[2021-12-17 10:04:17,885: INFO/ForkPoolWorker-1] Task celery_app.add[600f06a9-c4de-4d77-bf6a-d6aa2a696afb] succeeded in 100.08728766800004s: 239
[2021-12-17 11:01:15,427: INFO/MainProcess] Task celery_app.add[d5be0240-f061-451f-9747-9888fd89ebac] received
[2021-12-17 11:02:55,581: INFO/ForkPoolWorker-1] Task celery_app.add[d5be0240-f061-451f-9747-9888fd89ebac] succeeded in 100.18319533700014s: 65
[2021-12-17 11:24:36,448: INFO/MainProcess] Connected to redis://redis:6379/0
[2021-12-17 11:24:36,468: INFO/MainProcess] mingle: searching for neighbors
[2021-12-17 11:24:37,494: INFO/MainProcess] mingle: all alone
[2021-12-17 11:24:37,523: INFO/MainProcess] celery@worker ready.
[2021-12-17 14:01:38,417: INFO/MainProcess] Task celery_app.add[1a58468f-1529-4d42-a077-1593264b8fe4] received
[2021-12-17 14:01:58,523: ERROR/ForkPoolWorker-1] Task celery_app.add[1a58468f-1529-4d42-a077-1593264b8fe4] raised unexpected: TypeError("unsupported operand type(s) for +: 'NoneType' and 'NoneType'")
Traceback (most recent call last):
  File "/usr/local/lib/python3.10/site-packages/celery/app/trace.py", line 451, in trace_task
    R = retval = fun(*args, **kwargs)
  File "/usr/local/lib/python3.10/site-packages/celery/app/trace.py", line 734, in __protected_call__
    return self.run(*args, **kwargs)
  File "/app/celery_app.py", line 13, in add
    return x + y
TypeError: unsupported operand type(s) for +: 'NoneType' and 'NoneType'
[2021-12-17 15:06:01,807: ERROR/MainProcess] Received unregistered task of type 'celery_app.add_task'.
The message has been ignored and discarded.

Did you remember to import the module containing this task?
Or maybe you're using relative imports?

Please see
http://docs.celeryq.org/en/latest/internals/protocol.html
for more information.

The full contents of the message body was:
b'[[3, 5], {}, {"callbacks": null, "errbacks": null, "chain": null, "chord": null}]' (81b)
Traceback (most recent call last):
  File "/usr/local/lib/python3.10/site-packages/celery/worker/consumer/consumer.py", line 581, in on_task_received
    strategy = strategies[type_]
KeyError: 'celery_app.add_task'
[2021-12-17 15:07:58,315: ERROR/MainProcess] Received unregistered task of type 'celery_app.add_task'.
The message has been ignored and discarded.

Did you remember to import the module containing this task?
Or maybe you're using relative imports?

Please see
http://docs.celeryq.org/en/latest/internals/protocol.html
for more information.

The full contents of the message body was:
b'[[3, 5], {}, {"callbacks": null, "errbacks": null, "chain": null, "chord": null}]' (81b)
Traceback (most recent call last):
  File "/usr/local/lib/python3.10/site-packages/celery/worker/consumer/consumer.py", line 581, in on_task_received
    strategy = strategies[type_]
KeyError: 'celery_app.add_task'
[2021-12-17 15:09:21,557: ERROR/MainProcess] Received unregistered task of type 'celery_app.add_task'.
The message has been ignored and discarded.

Did you remember to import the module containing this task?
Or maybe you're using relative imports?

Please see
http://docs.celeryq.org/en/latest/internals/protocol.html
for more information.

The full contents of the message body was:
b'[[3, 6], {}, {"callbacks": null, "errbacks": null, "chain": null, "chord": null}]' (81b)
Traceback (most recent call last):
  File "/usr/local/lib/python3.10/site-packages/celery/worker/consumer/consumer.py", line 581, in on_task_received
    strategy = strategies[type_]
KeyError: 'celery_app.add_task'
[2021-12-17 15:09:37,219: ERROR/MainProcess] Received unregistered task of type 'celery_app.add_task'.
The message has been ignored and discarded.

Did you remember to import the module containing this task?
Or maybe you're using relative imports?

Please see
http://docs.celeryq.org/en/latest/internals/protocol.html
for more information.

The full contents of the message body was:
b'[[3, 7], {}, {"callbacks": null, "errbacks": null, "chain": null, "chord": null}]' (81b)
Traceback (most recent call last):
  File "/usr/local/lib/python3.10/site-packages/celery/worker/consumer/consumer.py", line 581, in on_task_received
    strategy = strategies[type_]
KeyError: 'celery_app.add_task'
[2021-12-17 15:11:41,105: ERROR/MainProcess] Received unregistered task of type 'celery_app.add_task'.
The message has been ignored and discarded.

Did you remember to import the module containing this task?
Or maybe you're using relative imports?

Please see
http://docs.celeryq.org/en/latest/internals/protocol.html
for more information.

The full contents of the message body was:
b'[[3, 7], {}, {"callbacks": null, "errbacks": null, "chain": null, "chord": null}]' (81b)
Traceback (most recent call last):
  File "/usr/local/lib/python3.10/site-packages/celery/worker/consumer/consumer.py", line 581, in on_task_received
    strategy = strategies[type_]
KeyError: 'celery_app.add_task'
[2021-12-17 15:13:26,786: INFO/MainProcess] Connected to redis://redis:6379/0
[2021-12-17 15:13:26,804: INFO/MainProcess] mingle: searching for neighbors
[2021-12-17 15:13:27,833: INFO/MainProcess] mingle: all alone
[2021-12-17 15:13:27,864: INFO/MainProcess] celery@worker ready.
[2021-12-17 15:14:46,480: INFO/MainProcess] Task celery_app.add_task[e9f5ef11-a479-4888-a64b-daf8534de535] received
[2021-12-17 15:14:46,494: INFO/MainProcess] Task celery_app.add_task[8dc58463-564c-4cf8-bbd7-f6c858bba181] received
[2021-12-17 15:15:06,480: INFO/ForkPoolWorker-1] Task celery_app.add_task[e9f5ef11-a479-4888-a64b-daf8534de535] succeeded in 20.027662699998473s: 10
[2021-12-17 15:15:06,507: INFO/ForkPoolWorker-2] Task celery_app.add_task[8dc58463-564c-4cf8-bbd7-f6c858bba181] succeeded in 20.033075800001825s: 10
[2021-12-17 15:55:24,826: INFO/MainProcess] Task celery_app.add_task[9b918b1a-80ec-4ebe-8bcf-b8c1142fce86] received
[2021-12-17 15:55:24,851: INFO/MainProcess] Task celery_app.add_task[9f0b3767-e58b-4d9d-84eb-fd4067873181] received
[2021-12-17 15:55:44,845: INFO/ForkPoolWorker-1] Task celery_app.add_task[9b918b1a-80ec-4ebe-8bcf-b8c1142fce86] succeeded in 20.006840300000476s: 3
[2021-12-17 15:55:44,883: INFO/ForkPoolWorker-2] Task celery_app.add_task[9f0b3767-e58b-4d9d-84eb-fd4067873181] succeeded in 20.022758499999327s: 3
[2021-12-17 15:56:40,097: INFO/MainProcess] Task celery_app.add_task[e690423f-c0b0-4739-8870-fe228320a124] received
[2021-12-17 15:56:40,110: INFO/MainProcess] Task celery_app.add_task[acd52c55-9a9d-4519-8345-6d05defd984b] received
[2021-12-17 15:57:00,091: INFO/ForkPoolWorker-1] Task celery_app.add_task[e690423f-c0b0-4739-8870-fe228320a124] succeeded in 20.022993900001893s: 6
[2021-12-17 15:57:00,095: INFO/ForkPoolWorker-2] Task celery_app.add_task[acd52c55-9a9d-4519-8345-6d05defd984b] succeeded in 20.009210100000928s: 5
[2021-12-17 15:59:34,712: INFO/MainProcess] Connected to redis://redis:6379/0
[2021-12-17 15:59:34,725: INFO/MainProcess] mingle: searching for neighbors
[2021-12-17 15:59:35,764: INFO/MainProcess] mingle: all alone
[2021-12-17 15:59:35,794: INFO/MainProcess] celery@worker ready.
[2021-12-17 16:00:29,635: INFO/MainProcess] Task celery_app.add_task[a1300972-a965-4359-b9a1-0080ec0153ac] received
[2021-12-17 16:00:29,649: INFO/MainProcess] Task celery_app.add_task[a2c3a8e6-6451-4f25-abee-d748f7af4fd3] received
[2021-12-17 16:02:09,810: INFO/ForkPoolWorker-1] Task celery_app.add_task[a1300972-a965-4359-b9a1-0080ec0153ac] succeeded in 100.0148868000033s: 10
[2021-12-17 16:02:09,832: INFO/ForkPoolWorker-2] Task celery_app.add_task[a2c3a8e6-6451-4f25-abee-d748f7af4fd3] succeeded in 100.02174519999971s: 10
[2021-12-17 16:16:26,296: INFO/MainProcess] Task celery_app.add_task[028e381b-cb28-4a51-a914-f8ac5db0a8da] received
[2021-12-17 16:18:06,262: INFO/ForkPoolWorker-1] Task celery_app.add_task[028e381b-cb28-4a51-a914-f8ac5db0a8da] succeeded in 100.06169070000033s: 10
[2021-12-17 16:18:42,882: INFO/MainProcess] Task celery_app.add_task[b0144b1b-e24b-43b5-89ec-08cc9d47a192] received
[2021-12-17 16:20:22,835: INFO/ForkPoolWorker-1] Task celery_app.add_task[b0144b1b-e24b-43b5-89ec-08cc9d47a192] succeeded in 100.08125350000046s: 10
[2021-12-17 16:27:37,063: INFO/MainProcess] Task celery_app.add_task[58aaffad-988d-4b9f-88b6-1d7dc4f8ec14] received
[2021-12-17 16:29:17,032: ERROR/ForkPoolWorker-1] Task celery_app.add_task[58aaffad-988d-4b9f-88b6-1d7dc4f8ec14] raised unexpected: TypeError("unsupported operand type(s) for +: 'NoneType' and 'NoneType'")
Traceback (most recent call last):
  File "/usr/local/lib/python3.10/site-packages/celery/app/trace.py", line 451, in trace_task
    R = retval = fun(*args, **kwargs)
  File "/usr/local/lib/python3.10/site-packages/celery/app/trace.py", line 734, in __protected_call__
    return self.run(*args, **kwargs)
  File "/app/celery_app.py", line 13, in add_task
    return x + y
TypeError: unsupported operand type(s) for +: 'NoneType' and 'NoneType'
[2021-12-17 16:31:40,274: INFO/MainProcess] Task celery_app.add_task[0e2dda35-1293-4d54-9026-3a72087c42b7] received
[2021-12-17 16:33:20,190: INFO/ForkPoolWorker-1] Task celery_app.add_task[0e2dda35-1293-4d54-9026-3a72087c42b7] succeeded in 100.04280069999731s: 8
[2021-12-17 16:34:28,287: INFO/MainProcess] Task celery_app.add_task[ed7b089a-2e78-44cc-8619-7b74a6665291] received
[2021-12-17 16:36:08,254: ERROR/ForkPoolWorker-1] Task celery_app.add_task[ed7b089a-2e78-44cc-8619-7b74a6665291] raised unexpected: TypeError("unsupported operand type(s) for +: 'NoneType' and 'NoneType'")
Traceback (most recent call last):
  File "/usr/local/lib/python3.10/site-packages/celery/app/trace.py", line 451, in trace_task
    R = retval = fun(*args, **kwargs)
  File "/usr/local/lib/python3.10/site-packages/celery/app/trace.py", line 734, in __protected_call__
    return self.run(*args, **kwargs)
  File "/app/celery_app.py", line 13, in add_task
    return int(x) + int(y)
TypeError: unsupported operand type(s) for +: 'NoneType' and 'NoneType'
[2021-12-17 16:42:01,295: INFO/MainProcess] Task celery_app.add_task[aa0dab03-bdc6-40d8-b9b1-acbc1e313545] received
[2021-12-17 16:43:41,228: ERROR/ForkPoolWorker-1] Task celery_app.add_task[aa0dab03-bdc6-40d8-b9b1-acbc1e313545] raised unexpected: TypeError("unsupported operand type(s) for +: 'NoneType' and 'NoneType'")
Traceback (most recent call last):
  File "/usr/local/lib/python3.10/site-packages/celery/app/trace.py", line 451, in trace_task
    R = retval = fun(*args, **kwargs)
  File "/usr/local/lib/python3.10/site-packages/celery/app/trace.py", line 734, in __protected_call__
    return self.run(*args, **kwargs)
  File "/app/celery_app.py", line 13, in add_task
    return x + y
TypeError: unsupported operand type(s) for +: 'NoneType' and 'NoneType'
[2021-12-17 16:47:27,465: INFO/MainProcess] Task celery_app.add_task[ed53719c-1e59-4b48-956c-e46c461aa5d1] received
[2021-12-17 16:49:07,465: ERROR/ForkPoolWorker-1] Task celery_app.add_task[ed53719c-1e59-4b48-956c-e46c461aa5d1] raised unexpected: TypeError("unsupported operand type(s) for +: 'NoneType' and 'NoneType'")
Traceback (most recent call last):
  File "/usr/local/lib/python3.10/site-packages/celery/app/trace.py", line 451, in trace_task
    R = retval = fun(*args, **kwargs)
  File "/usr/local/lib/python3.10/site-packages/celery/app/trace.py", line 734, in __protected_call__
    return self.run(*args, **kwargs)
  File "/app/celery_app.py", line 13, in add_task
    return x + y
TypeError: unsupported operand type(s) for +: 'NoneType' and 'NoneType'
[2021-12-17 16:51:30,001: INFO/MainProcess] Task celery_app.add_task[d11f249c-08b3-4b86-b262-f62d02929275] received
[2021-12-17 16:53:10,013: ERROR/ForkPoolWorker-1] Task celery_app.add_task[d11f249c-08b3-4b86-b262-f62d02929275] raised unexpected: TypeError("unsupported operand type(s) for +: 'NoneType' and 'NoneType'")
Traceback (most recent call last):
  File "/usr/local/lib/python3.10/site-packages/celery/app/trace.py", line 451, in trace_task
    R = retval = fun(*args, **kwargs)
  File "/usr/local/lib/python3.10/site-packages/celery/app/trace.py", line 734, in __protected_call__
    return self.run(*args, **kwargs)
  File "/app/celery_app.py", line 13, in add_task
    return x + y
TypeError: unsupported operand type(s) for +: 'NoneType' and 'NoneType'
[2021-12-17 16:54:25,730: INFO/MainProcess] Task celery_app.add_task[b74f4db2-5b7d-4dab-a8b6-667b15b25a7f] received
[2021-12-17 16:56:05,738: INFO/ForkPoolWorker-1] Task celery_app.add_task[b74f4db2-5b7d-4dab-a8b6-667b15b25a7f] succeeded in 100.0969045999991s: 8
[2021-12-17 17:09:40,345: INFO/MainProcess] Task celery_app.add_task[a7fbb3b6-3446-4ab0-bec7-d204b0e7222e] received
[2021-12-17 17:11:20,330: ERROR/ForkPoolWorker-1] Task celery_app.add_task[a7fbb3b6-3446-4ab0-bec7-d204b0e7222e] raised unexpected: TypeError("unsupported operand type(s) for +: 'NoneType' and 'NoneType'")
Traceback (most recent call last):
  File "/usr/local/lib/python3.10/site-packages/celery/app/trace.py", line 451, in trace_task
    R = retval = fun(*args, **kwargs)
  File "/usr/local/lib/python3.10/site-packages/celery/app/trace.py", line 734, in __protected_call__
    return self.run(*args, **kwargs)
  File "/app/celery_app.py", line 13, in add_task
    return x + y
TypeError: unsupported operand type(s) for +: 'NoneType' and 'NoneType'
[2021-12-17 17:23:21,900: INFO/MainProcess] Task celery_app.add_task[f8665e3f-af03-46a1-8fbd-7ff570ac031b] received
[2021-12-17 17:25:01,813: INFO/ForkPoolWorker-1] Task celery_app.add_task[f8665e3f-af03-46a1-8fbd-7ff570ac031b] succeeded in 100.01175049999802s: 7
[2021-12-17 17:26:54,448: INFO/MainProcess] Task celery_app.add_task[7c8465d3-9a38-43e1-829e-ab21cf6f224c] received
[2021-12-17 17:26:54,465: INFO/MainProcess] Task celery_app.add_task[6a0fdb54-910d-448b-84fd-3921c062efbc] received
[2021-12-17 17:28:34,415: INFO/ForkPoolWorker-1] Task celery_app.add_task[7c8465d3-9a38-43e1-829e-ab21cf6f224c] succeeded in 100.06207319999885s: 10
[2021-12-17 17:28:34,430: INFO/ForkPoolWorker-2] Task celery_app.add_task[6a0fdb54-910d-448b-84fd-3921c062efbc] succeeded in 100.05132009999943s: 10
[2021-12-17 17:29:31,136: INFO/MainProcess] Task celery_app.add_task[dbcea43f-dd0c-4ac9-99cb-de4a897d75a7] received
[2021-12-17 17:31:11,144: INFO/ForkPoolWorker-1] Task celery_app.add_task[dbcea43f-dd0c-4ac9-99cb-de4a897d75a7] succeeded in 100.10138749999896s: 17
[2021-12-17 17:40:59,691: INFO/MainProcess] Task celery_app.add_task[ac0e1290-0f7b-493a-b7e5-b757898c8214] received
[2021-12-17 17:42:39,652: INFO/ForkPoolWorker-1] Task celery_app.add_task[ac0e1290-0f7b-493a-b7e5-b757898c8214] succeeded in 100.05344590000095s: 7
[2021-12-21 14:06:00,528: INFO/MainProcess] Connected to redis://redis:6379/0
[2021-12-21 14:06:00,555: INFO/MainProcess] mingle: searching for neighbors
[2021-12-21 14:06:01,635: INFO/MainProcess] mingle: all alone
[2021-12-21 14:06:01,657: INFO/MainProcess] celery@worker ready.
[2021-12-21 14:17:56,561: INFO/MainProcess] Task celery_app.add_task[322b636a-808d-4d7d-87d3-8caef6973d11] received
[2021-12-21 14:18:11,638: INFO/ForkPoolWorker-1] Task celery_app.add_task[322b636a-808d-4d7d-87d3-8caef6973d11] succeeded in 15.081349063999824s: 10
[2021-12-21 16:26:50,852: INFO/MainProcess] Connected to redis://redis:6379/0
[2021-12-21 16:26:50,863: INFO/MainProcess] mingle: searching for neighbors
[2021-12-21 16:26:51,888: INFO/MainProcess] mingle: all alone
[2021-12-21 16:26:51,909: INFO/MainProcess] celery@worker ready.
[2021-12-21 16:27:37,813: INFO/MainProcess] Task celery_app.add_task[80cb5716-f44b-42ae-868b-3c3e4b193b3e] received
[2021-12-22 11:43:21,464: INFO/MainProcess] Connected to redis://redis:6379/0
[2021-12-22 11:43:21,475: INFO/MainProcess] mingle: searching for neighbors
[2021-12-22 11:43:22,494: INFO/MainProcess] mingle: all alone
[2021-12-22 11:43:22,517: INFO/MainProcess] celery@worker ready.
[2021-12-22 13:49:03,358: INFO/MainProcess] Task celery_app.add_task[b8bf8908-629e-4f97-a686-91f99c7bc855] received
[2021-12-22 14:22:52,553: INFO/MainProcess] Task celery_app.add_task[a6472ecf-d027-4ec7-a458-9052a8bbd4c8] received
[2021-12-22 16:16:55,416: INFO/MainProcess] Connected to redis://redis:6379/0
[2021-12-22 16:16:55,425: INFO/MainProcess] mingle: searching for neighbors
[2021-12-22 16:16:56,447: INFO/MainProcess] mingle: all alone
[2021-12-22 16:16:56,470: INFO/MainProcess] celery@worker ready.
[2021-12-22 16:17:55,714: INFO/MainProcess] Task celery_app.add_task[645eca6b-1e31-4f2b-9a18-ec49ab27a114] received
[2021-12-22 16:19:35,742: ERROR/ForkPoolWorker-1] Task celery_app.add_task[645eca6b-1e31-4f2b-9a18-ec49ab27a114] raised unexpected: gaierror(-2, 'Name or service not known')
Traceback (most recent call last):
  File "/usr/local/lib/python3.10/site-packages/celery/app/trace.py", line 451, in trace_task
    R = retval = fun(*args, **kwargs)
  File "/usr/local/lib/python3.10/site-packages/celery/app/trace.py", line 734, in __protected_call__
    return self.run(*args, **kwargs)
  File "/app/celery_app.py", line 15, in add_task
    rdb.set_trace()
  File "/usr/local/lib/python3.10/site-packages/celery/contrib/rdb.py", line 188, in set_trace
    return debugger().set_trace(frame)
  File "/usr/local/lib/python3.10/site-packages/celery/contrib/rdb.py", line 180, in debugger
    rdb = _current[0] = Rdb()
  File "/usr/local/lib/python3.10/site-packages/celery/contrib/rdb.py", line 98, in __init__
    self._sock, this_port = self.get_avail_port(
  File "/usr/local/lib/python3.10/site-packages/celery/contrib/rdb.py", line 128, in get_avail_port
    _sock.bind((host, this_port))
socket.gaierror: [Errno -2] Name or service not known
[2021-12-22 16:24:56,180: INFO/MainProcess] Connected to redis://redis:6379/0
[2021-12-22 16:24:56,189: INFO/MainProcess] mingle: searching for neighbors
[2021-12-22 16:24:57,213: INFO/MainProcess] mingle: all alone
[2021-12-22 16:24:57,236: INFO/MainProcess] celery@worker ready.
[2021-12-22 16:25:21,125: INFO/MainProcess] Task celery_app.add_task[6a78e045-64e2-431b-adc8-af1a6ad94ed6] received
[2021-12-22 16:25:36,173: ERROR/ForkPoolWorker-1] Task celery_app.add_task[6a78e045-64e2-431b-adc8-af1a6ad94ed6] raised unexpected: gaierror(-2, 'Name or service not known')
Traceback (most recent call last):
  File "/usr/local/lib/python3.10/site-packages/celery/app/trace.py", line 451, in trace_task
    R = retval = fun(*args, **kwargs)
  File "/usr/local/lib/python3.10/site-packages/celery/app/trace.py", line 734, in __protected_call__
    return self.run(*args, **kwargs)
  File "/app/celery_app.py", line 15, in add_task
    rdb.set_trace()
  File "/usr/local/lib/python3.10/site-packages/celery/contrib/rdb.py", line 188, in set_trace
    return debugger().set_trace(frame)
  File "/usr/local/lib/python3.10/site-packages/celery/contrib/rdb.py", line 180, in debugger
    rdb = _current[0] = Rdb()
  File "/usr/local/lib/python3.10/site-packages/celery/contrib/rdb.py", line 98, in __init__
    self._sock, this_port = self.get_avail_port(
  File "/usr/local/lib/python3.10/site-packages/celery/contrib/rdb.py", line 128, in get_avail_port
    _sock.bind((host, this_port))
socket.gaierror: [Errno -2] Name or service not known
[2021-12-22 16:27:45,302: INFO/MainProcess] Connected to redis://redis:6379/0
[2021-12-22 16:27:45,315: INFO/MainProcess] mingle: searching for neighbors
[2021-12-22 16:27:46,340: INFO/MainProcess] mingle: all alone
[2021-12-22 16:27:46,360: INFO/MainProcess] celery@worker ready.
[2021-12-22 16:28:33,306: INFO/MainProcess] Task celery_app.add_task[7e3aa18a-004a-42d7-9156-e04eaa27f3e9] received
[2022-01-07 14:24:31,226: INFO/MainProcess] Connected to redis://redis:6379/0
[2022-01-07 14:24:31,237: INFO/MainProcess] mingle: searching for neighbors
[2022-01-07 14:24:32,264: INFO/MainProcess] mingle: all alone
[2022-01-07 14:24:32,285: INFO/MainProcess] celery@worker ready.
[2022-01-07 14:24:38,055: INFO/MainProcess] Task celery_app.add_task[90e1e94c-4972-4826-bb79-f1c0ff91fccc] received
[2022-01-07 14:26:35,642: INFO/MainProcess] Connected to redis://redis:6379/0
[2022-01-07 14:26:35,651: INFO/MainProcess] mingle: searching for neighbors
[2022-01-07 14:26:36,671: INFO/MainProcess] mingle: all alone
[2022-01-07 14:26:36,690: INFO/MainProcess] celery@worker ready.
[2022-01-07 14:26:42,466: INFO/MainProcess] Task celery_app.add_task[71439c35-2a10-49e3-9386-db9d42a43fbe] received
[2022-01-07 14:26:52,485: WARNING/ForkPoolWorker-1] pdb is running on 0.0.0.0:4444
[2022-01-07 14:27:14,267: ERROR/ForkPoolWorker-1] Task celery_app.add_task[71439c35-2a10-49e3-9386-db9d42a43fbe] raised unexpected: BdbQuit()
Traceback (most recent call last):
  File "/usr/local/lib/python3.10/site-packages/celery/app/trace.py", line 451, in trace_task
    R = retval = fun(*args, **kwargs)
  File "/usr/local/lib/python3.10/site-packages/celery/app/trace.py", line 734, in __protected_call__
    return self.run(*args, **kwargs)
  File "/app/celery_app.py", line 18, in add_task
    return result
  File "/app/celery_app.py", line 18, in add_task
    return result
  File "/usr/local/lib/python3.10/bdb.py", line 90, in trace_dispatch
    return self.dispatch_line(frame)
  File "/usr/local/lib/python3.10/bdb.py", line 115, in dispatch_line
    if self.quitting: raise BdbQuit
bdb.BdbQuit
[2022-01-07 14:28:43,196: INFO/MainProcess] Task celery_app.add_task[053b0291-6ed1-4dd4-b25f-69a68dbcf1b6] received
[2022-01-07 14:28:53,205: WARNING/ForkPoolWorker-1] pdb is running on 0.0.0.0:4444
[2022-01-07 14:29:31,499: INFO/MainProcess] Connected to redis://redis:6379/0
[2022-01-07 14:29:31,510: INFO/MainProcess] mingle: searching for neighbors
[2022-01-07 14:29:32,513: INFO/MainProcess] mingle: all alone
[2022-01-07 14:29:32,531: INFO/MainProcess] celery@worker ready.
[2022-01-07 14:29:35,510: INFO/MainProcess] Task celery_app.add_task[a5fb7ab9-3a75-4867-ae33-fcfa26de4ed0] received
[2022-01-07 14:29:45,526: WARNING/ForkPoolWorker-1] pdb is running on 0.0.0.0:4444
[2022-01-07 14:32:41,731: ERROR/ForkPoolWorker-1] Task celery_app.add_task[a5fb7ab9-3a75-4867-ae33-fcfa26de4ed0] raised unexpected: BdbQuit()
Traceback (most recent call last):
  File "/usr/local/lib/python3.10/site-packages/celery/app/trace.py", line 451, in trace_task
    R = retval = fun(*args, **kwargs)
  File "/usr/local/lib/python3.10/site-packages/celery/app/trace.py", line 734, in __protected_call__
    return self.run(*args, **kwargs)
  File "/app/celery_app.py", line 18, in add_task
    return result
  File "/usr/local/lib/python3.10/bdb.py", line 94, in trace_dispatch
    return self.dispatch_return(frame, arg)
  File "/usr/local/lib/python3.10/bdb.py", line 156, in dispatch_return
    if self.quitting: raise BdbQuit
bdb.BdbQuit
