[2021-12-17 09:50:39,422: INFO/MainProcess] Connected to redis://redis:6379/0
[2021-12-17 09:50:39,460: INFO/MainProcess] mingle: searching for neighbors
[2021-12-17 09:50:40,496: INFO/MainProcess] mingle: all alone
[2021-12-17 09:50:40,526: INFO/MainProcess] celery@worker ready.
[2021-12-17 09:51:14,542: INFO/MainProcess] Task celery_app.add[c96617b1-5cf7-423c-9e51-cd74b2e9c574] received
[2021-12-17 09:52:54,510: INFO/ForkPoolWorker-1] Task celery_app.add[c96617b1-5cf7-423c-9e51-cd74b2e9c574] succeeded in 100.04670926400013s: 7
[2021-12-17 09:53:14,306: INFO/MainProcess] Task celery_app.add[f3b7edd6-2ca0-4b32-a0a9-1086421c1ead] received
[2021-12-17 09:54:54,263: INFO/ForkPoolWorker-1] Task celery_app.add[f3b7edd6-2ca0-4b32-a0a9-1086421c1ead] succeeded in 100.03439320000007s: 105
[2021-12-17 10:02:37,874: INFO/MainProcess] Task celery_app.add[600f06a9-c4de-4d77-bf6a-d6aa2a696afb] received
[2021-12-17 10:04:17,885: INFO/ForkPoolWorker-1] Task celery_app.add[600f06a9-c4de-4d77-bf6a-d6aa2a696afb] succeeded in 100.08728766800004s: 239
[2021-12-17 11:01:15,427: INFO/MainProcess] Task celery_app.add[d5be0240-f061-451f-9747-9888fd89ebac] received
[2021-12-17 11:02:55,581: INFO/ForkPoolWorker-1] Task celery_app.add[d5be0240-f061-451f-9747-9888fd89ebac] succeeded in 100.18319533700014s: 65
[2021-12-17 11:24:36,448: INFO/MainProcess] Connected to redis://redis:6379/0
[2021-12-17 11:24:36,468: INFO/MainProcess] mingle: searching for neighbors
[2021-12-17 11:24:37,494: INFO/MainProcess] mingle: all alone
[2021-12-17 11:24:37,523: INFO/MainProcess] celery@worker ready.
[2021-12-17 14:01:38,417: INFO/MainProcess] Task celery_app.add[1a58468f-1529-4d42-a077-1593264b8fe4] received
[2021-12-17 14:01:58,523: ERROR/ForkPoolWorker-1] Task celery_app.add[1a58468f-1529-4d42-a077-1593264b8fe4] raised unexpected: TypeError("unsupported operand type(s) for +: 'NoneType' and 'NoneType'")
Traceback (most recent call last):
  File "/usr/local/lib/python3.10/site-packages/celery/app/trace.py", line 451, in trace_task
    R = retval = fun(*args, **kwargs)
  File "/usr/local/lib/python3.10/site-packages/celery/app/trace.py", line 734, in __protected_call__
    return self.run(*args, **kwargs)
  File "/app/celery_app.py", line 13, in add
    return x + y
TypeError: unsupported operand type(s) for +: 'NoneType' and 'NoneType'
[2021-12-17 15:06:01,807: ERROR/MainProcess] Received unregistered task of type 'celery_app.add_task'.
The message has been ignored and discarded.

Did you remember to import the module containing this task?
Or maybe you're using relative imports?

Please see
http://docs.celeryq.org/en/latest/internals/protocol.html
for more information.

The full contents of the message body was:
b'[[3, 5], {}, {"callbacks": null, "errbacks": null, "chain": null, "chord": null}]' (81b)
Traceback (most recent call last):
  File "/usr/local/lib/python3.10/site-packages/celery/worker/consumer/consumer.py", line 581, in on_task_received
    strategy = strategies[type_]
KeyError: 'celery_app.add_task'
[2021-12-17 15:07:58,315: ERROR/MainProcess] Received unregistered task of type 'celery_app.add_task'.
The message has been ignored and discarded.

Did you remember to import the module containing this task?
Or maybe you're using relative imports?

Please see
http://docs.celeryq.org/en/latest/internals/protocol.html
for more information.

The full contents of the message body was:
b'[[3, 5], {}, {"callbacks": null, "errbacks": null, "chain": null, "chord": null}]' (81b)
Traceback (most recent call last):
  File "/usr/local/lib/python3.10/site-packages/celery/worker/consumer/consumer.py", line 581, in on_task_received
    strategy = strategies[type_]
KeyError: 'celery_app.add_task'
[2021-12-17 15:09:21,557: ERROR/MainProcess] Received unregistered task of type 'celery_app.add_task'.
The message has been ignored and discarded.

Did you remember to import the module containing this task?
Or maybe you're using relative imports?

Please see
http://docs.celeryq.org/en/latest/internals/protocol.html
for more information.

The full contents of the message body was:
b'[[3, 6], {}, {"callbacks": null, "errbacks": null, "chain": null, "chord": null}]' (81b)
Traceback (most recent call last):
  File "/usr/local/lib/python3.10/site-packages/celery/worker/consumer/consumer.py", line 581, in on_task_received
    strategy = strategies[type_]
KeyError: 'celery_app.add_task'
[2021-12-17 15:09:37,219: ERROR/MainProcess] Received unregistered task of type 'celery_app.add_task'.
The message has been ignored and discarded.

Did you remember to import the module containing this task?
Or maybe you're using relative imports?

Please see
http://docs.celeryq.org/en/latest/internals/protocol.html
for more information.

The full contents of the message body was:
b'[[3, 7], {}, {"callbacks": null, "errbacks": null, "chain": null, "chord": null}]' (81b)
Traceback (most recent call last):
  File "/usr/local/lib/python3.10/site-packages/celery/worker/consumer/consumer.py", line 581, in on_task_received
    strategy = strategies[type_]
KeyError: 'celery_app.add_task'
[2021-12-17 15:11:41,105: ERROR/MainProcess] Received unregistered task of type 'celery_app.add_task'.
The message has been ignored and discarded.

Did you remember to import the module containing this task?
Or maybe you're using relative imports?

Please see
http://docs.celeryq.org/en/latest/internals/protocol.html
for more information.

The full contents of the message body was:
b'[[3, 7], {}, {"callbacks": null, "errbacks": null, "chain": null, "chord": null}]' (81b)
Traceback (most recent call last):
  File "/usr/local/lib/python3.10/site-packages/celery/worker/consumer/consumer.py", line 581, in on_task_received
    strategy = strategies[type_]
KeyError: 'celery_app.add_task'
[2021-12-17 15:13:26,786: INFO/MainProcess] Connected to redis://redis:6379/0
[2021-12-17 15:13:26,804: INFO/MainProcess] mingle: searching for neighbors
[2021-12-17 15:13:27,833: INFO/MainProcess] mingle: all alone
[2021-12-17 15:13:27,864: INFO/MainProcess] celery@worker ready.
[2021-12-17 15:14:46,480: INFO/MainProcess] Task celery_app.add_task[e9f5ef11-a479-4888-a64b-daf8534de535] received
[2021-12-17 15:14:46,494: INFO/MainProcess] Task celery_app.add_task[8dc58463-564c-4cf8-bbd7-f6c858bba181] received
[2021-12-17 15:15:06,480: INFO/ForkPoolWorker-1] Task celery_app.add_task[e9f5ef11-a479-4888-a64b-daf8534de535] succeeded in 20.027662699998473s: 10
[2021-12-17 15:15:06,507: INFO/ForkPoolWorker-2] Task celery_app.add_task[8dc58463-564c-4cf8-bbd7-f6c858bba181] succeeded in 20.033075800001825s: 10
[2021-12-17 15:55:24,826: INFO/MainProcess] Task celery_app.add_task[9b918b1a-80ec-4ebe-8bcf-b8c1142fce86] received
[2021-12-17 15:55:24,851: INFO/MainProcess] Task celery_app.add_task[9f0b3767-e58b-4d9d-84eb-fd4067873181] received
[2021-12-17 15:55:44,845: INFO/ForkPoolWorker-1] Task celery_app.add_task[9b918b1a-80ec-4ebe-8bcf-b8c1142fce86] succeeded in 20.006840300000476s: 3
[2021-12-17 15:55:44,883: INFO/ForkPoolWorker-2] Task celery_app.add_task[9f0b3767-e58b-4d9d-84eb-fd4067873181] succeeded in 20.022758499999327s: 3
[2021-12-17 15:56:40,097: INFO/MainProcess] Task celery_app.add_task[e690423f-c0b0-4739-8870-fe228320a124] received
[2021-12-17 15:56:40,110: INFO/MainProcess] Task celery_app.add_task[acd52c55-9a9d-4519-8345-6d05defd984b] received
[2021-12-17 15:57:00,091: INFO/ForkPoolWorker-1] Task celery_app.add_task[e690423f-c0b0-4739-8870-fe228320a124] succeeded in 20.022993900001893s: 6
[2021-12-17 15:57:00,095: INFO/ForkPoolWorker-2] Task celery_app.add_task[acd52c55-9a9d-4519-8345-6d05defd984b] succeeded in 20.009210100000928s: 5
[2021-12-17 15:59:34,712: INFO/MainProcess] Connected to redis://redis:6379/0
[2021-12-17 15:59:34,725: INFO/MainProcess] mingle: searching for neighbors
[2021-12-17 15:59:35,764: INFO/MainProcess] mingle: all alone
[2021-12-17 15:59:35,794: INFO/MainProcess] celery@worker ready.
[2021-12-17 16:00:29,635: INFO/MainProcess] Task celery_app.add_task[a1300972-a965-4359-b9a1-0080ec0153ac] received
[2021-12-17 16:00:29,649: INFO/MainProcess] Task celery_app.add_task[a2c3a8e6-6451-4f25-abee-d748f7af4fd3] received
[2021-12-17 16:02:09,810: INFO/ForkPoolWorker-1] Task celery_app.add_task[a1300972-a965-4359-b9a1-0080ec0153ac] succeeded in 100.0148868000033s: 10
[2021-12-17 16:02:09,832: INFO/ForkPoolWorker-2] Task celery_app.add_task[a2c3a8e6-6451-4f25-abee-d748f7af4fd3] succeeded in 100.02174519999971s: 10
[2021-12-17 16:16:26,296: INFO/MainProcess] Task celery_app.add_task[028e381b-cb28-4a51-a914-f8ac5db0a8da] received
[2021-12-17 16:18:06,262: INFO/ForkPoolWorker-1] Task celery_app.add_task[028e381b-cb28-4a51-a914-f8ac5db0a8da] succeeded in 100.06169070000033s: 10
[2021-12-17 16:18:42,882: INFO/MainProcess] Task celery_app.add_task[b0144b1b-e24b-43b5-89ec-08cc9d47a192] received
[2021-12-17 16:20:22,835: INFO/ForkPoolWorker-1] Task celery_app.add_task[b0144b1b-e24b-43b5-89ec-08cc9d47a192] succeeded in 100.08125350000046s: 10
[2021-12-17 16:27:37,063: INFO/MainProcess] Task celery_app.add_task[58aaffad-988d-4b9f-88b6-1d7dc4f8ec14] received
[2021-12-17 16:29:17,032: ERROR/ForkPoolWorker-1] Task celery_app.add_task[58aaffad-988d-4b9f-88b6-1d7dc4f8ec14] raised unexpected: TypeError("unsupported operand type(s) for +: 'NoneType' and 'NoneType'")
Traceback (most recent call last):
  File "/usr/local/lib/python3.10/site-packages/celery/app/trace.py", line 451, in trace_task
    R = retval = fun(*args, **kwargs)
  File "/usr/local/lib/python3.10/site-packages/celery/app/trace.py", line 734, in __protected_call__
    return self.run(*args, **kwargs)
  File "/app/celery_app.py", line 13, in add_task
    return x + y
TypeError: unsupported operand type(s) for +: 'NoneType' and 'NoneType'
[2021-12-17 16:31:40,274: INFO/MainProcess] Task celery_app.add_task[0e2dda35-1293-4d54-9026-3a72087c42b7] received
[2021-12-17 16:33:20,190: INFO/ForkPoolWorker-1] Task celery_app.add_task[0e2dda35-1293-4d54-9026-3a72087c42b7] succeeded in 100.04280069999731s: 8
[2021-12-17 16:34:28,287: INFO/MainProcess] Task celery_app.add_task[ed7b089a-2e78-44cc-8619-7b74a6665291] received
[2021-12-17 16:36:08,254: ERROR/ForkPoolWorker-1] Task celery_app.add_task[ed7b089a-2e78-44cc-8619-7b74a6665291] raised unexpected: TypeError("unsupported operand type(s) for +: 'NoneType' and 'NoneType'")
Traceback (most recent call last):
  File "/usr/local/lib/python3.10/site-packages/celery/app/trace.py", line 451, in trace_task
    R = retval = fun(*args, **kwargs)
  File "/usr/local/lib/python3.10/site-packages/celery/app/trace.py", line 734, in __protected_call__
    return self.run(*args, **kwargs)
  File "/app/celery_app.py", line 13, in add_task
    return int(x) + int(y)
TypeError: unsupported operand type(s) for +: 'NoneType' and 'NoneType'
[2021-12-17 16:42:01,295: INFO/MainProcess] Task celery_app.add_task[aa0dab03-bdc6-40d8-b9b1-acbc1e313545] received
[2021-12-17 16:43:41,228: ERROR/ForkPoolWorker-1] Task celery_app.add_task[aa0dab03-bdc6-40d8-b9b1-acbc1e313545] raised unexpected: TypeError("unsupported operand type(s) for +: 'NoneType' and 'NoneType'")
Traceback (most recent call last):
  File "/usr/local/lib/python3.10/site-packages/celery/app/trace.py", line 451, in trace_task
    R = retval = fun(*args, **kwargs)
  File "/usr/local/lib/python3.10/site-packages/celery/app/trace.py", line 734, in __protected_call__
    return self.run(*args, **kwargs)
  File "/app/celery_app.py", line 13, in add_task
    return x + y
TypeError: unsupported operand type(s) for +: 'NoneType' and 'NoneType'
[2021-12-17 16:47:27,465: INFO/MainProcess] Task celery_app.add_task[ed53719c-1e59-4b48-956c-e46c461aa5d1] received
[2021-12-17 16:49:07,465: ERROR/ForkPoolWorker-1] Task celery_app.add_task[ed53719c-1e59-4b48-956c-e46c461aa5d1] raised unexpected: TypeError("unsupported operand type(s) for +: 'NoneType' and 'NoneType'")
Traceback (most recent call last):
  File "/usr/local/lib/python3.10/site-packages/celery/app/trace.py", line 451, in trace_task
    R = retval = fun(*args, **kwargs)
  File "/usr/local/lib/python3.10/site-packages/celery/app/trace.py", line 734, in __protected_call__
    return self.run(*args, **kwargs)
  File "/app/celery_app.py", line 13, in add_task
    return x + y
TypeError: unsupported operand type(s) for +: 'NoneType' and 'NoneType'
[2021-12-17 16:51:30,001: INFO/MainProcess] Task celery_app.add_task[d11f249c-08b3-4b86-b262-f62d02929275] received
[2021-12-17 16:53:10,013: ERROR/ForkPoolWorker-1] Task celery_app.add_task[d11f249c-08b3-4b86-b262-f62d02929275] raised unexpected: TypeError("unsupported operand type(s) for +: 'NoneType' and 'NoneType'")
Traceback (most recent call last):
  File "/usr/local/lib/python3.10/site-packages/celery/app/trace.py", line 451, in trace_task
    R = retval = fun(*args, **kwargs)
  File "/usr/local/lib/python3.10/site-packages/celery/app/trace.py", line 734, in __protected_call__
    return self.run(*args, **kwargs)
  File "/app/celery_app.py", line 13, in add_task
    return x + y
TypeError: unsupported operand type(s) for +: 'NoneType' and 'NoneType'
[2021-12-17 16:54:25,730: INFO/MainProcess] Task celery_app.add_task[b74f4db2-5b7d-4dab-a8b6-667b15b25a7f] received
[2021-12-17 16:56:05,738: INFO/ForkPoolWorker-1] Task celery_app.add_task[b74f4db2-5b7d-4dab-a8b6-667b15b25a7f] succeeded in 100.0969045999991s: 8
[2021-12-17 17:09:40,345: INFO/MainProcess] Task celery_app.add_task[a7fbb3b6-3446-4ab0-bec7-d204b0e7222e] received
[2021-12-17 17:11:20,330: ERROR/ForkPoolWorker-1] Task celery_app.add_task[a7fbb3b6-3446-4ab0-bec7-d204b0e7222e] raised unexpected: TypeError("unsupported operand type(s) for +: 'NoneType' and 'NoneType'")
Traceback (most recent call last):
  File "/usr/local/lib/python3.10/site-packages/celery/app/trace.py", line 451, in trace_task
    R = retval = fun(*args, **kwargs)
  File "/usr/local/lib/python3.10/site-packages/celery/app/trace.py", line 734, in __protected_call__
    return self.run(*args, **kwargs)
  File "/app/celery_app.py", line 13, in add_task
    return x + y
TypeError: unsupported operand type(s) for +: 'NoneType' and 'NoneType'
[2021-12-17 17:23:21,900: INFO/MainProcess] Task celery_app.add_task[f8665e3f-af03-46a1-8fbd-7ff570ac031b] received
[2021-12-17 17:25:01,813: INFO/ForkPoolWorker-1] Task celery_app.add_task[f8665e3f-af03-46a1-8fbd-7ff570ac031b] succeeded in 100.01175049999802s: 7
[2021-12-17 17:26:54,448: INFO/MainProcess] Task celery_app.add_task[7c8465d3-9a38-43e1-829e-ab21cf6f224c] received
[2021-12-17 17:26:54,465: INFO/MainProcess] Task celery_app.add_task[6a0fdb54-910d-448b-84fd-3921c062efbc] received
[2021-12-17 17:28:34,415: INFO/ForkPoolWorker-1] Task celery_app.add_task[7c8465d3-9a38-43e1-829e-ab21cf6f224c] succeeded in 100.06207319999885s: 10
[2021-12-17 17:28:34,430: INFO/ForkPoolWorker-2] Task celery_app.add_task[6a0fdb54-910d-448b-84fd-3921c062efbc] succeeded in 100.05132009999943s: 10
[2021-12-17 17:29:31,136: INFO/MainProcess] Task celery_app.add_task[dbcea43f-dd0c-4ac9-99cb-de4a897d75a7] received
[2021-12-17 17:31:11,144: INFO/ForkPoolWorker-1] Task celery_app.add_task[dbcea43f-dd0c-4ac9-99cb-de4a897d75a7] succeeded in 100.10138749999896s: 17
[2021-12-17 17:40:59,691: INFO/MainProcess] Task celery_app.add_task[ac0e1290-0f7b-493a-b7e5-b757898c8214] received
